<?xml version="1.0"?>

<robot xmlns:xacro="http://www.ros.org/wiki/xacro" name="ixnaminki_olinki">

    <xacro:property name="PI" value="3.14159265359" />
    <xacro:property name="effort" value="30.0" />
    <xacro:property name="velocity" value="10.0" />

    <link name="world"/>

    <link name="base_link">
        <visual>
            <origin xyz="-1.25 0.5 0.1" rpy="1.570795 0.0 0.0"/>
            <geometry>
                <mesh filename="package://ixnaminki_description/meshes/ASSY_TrenInferior/01_Chasis.STL" scale="0.004 0.004 0.004"/>
            </geometry>
        </visual>
    </link>

    <link name="02_EjePrincipal">
        <visual>
            <origin xyz="0.8 1.0 0.25" rpy="1.570795 0.0 0.0"/>
            <geometry>
                <mesh filename="package://ixnaminki_description/meshes/ASSY_TrenInferior/02_EjePrincipal.STL" scale="0.004 0.004 0.004"/>
            </geometry>
        </visual> 
    </link>

    <link name="02_EjePrincipal2">
        <visual>
            <origin xyz="-0.73 1.0 0.25" rpy="1.570795 0.0 0.0"/>
            <geometry>
                <mesh filename="package://ixnaminki_description/meshes/ASSY_TrenInferior/02_EjePrincipal.STL" scale="0.004 0.004 0.004"/>
            </geometry>
        </visual> 
    </link>

    <link name="01_PlateSprocket">
        <visual>
            <origin xyz="-1.0 1.0 0.0" rpy="1.570795 0.0 0.0"/>
            <geometry>
                <mesh filename="package://ixnaminki_description/meshes/ASSY_TrenInferior/PlateSprocket.STL" scale="0.004 0.004 0.004"/>
            </geometry>
        </visual> 
    </link>

    <link name="02_PlateSprocket">
        <visual>
            <origin xyz="-1.0 -1.0 0.0" rpy="1.570795 0.0 0.0"/>
            <geometry>
                <mesh filename="package://ixnaminki_description/meshes/ASSY_TrenInferior/PlateSprocket.STL" scale="0.004 0.004 0.004"/>
            </geometry>
        </visual> 
    </link>

    <link name="03_PlateSprocket">
        <visual>
            <origin xyz="0.55 1.0 0.0" rpy="1.570795 0.0 0.0"/>
            <geometry>
                <mesh filename="package://ixnaminki_description/meshes/ASSY_TrenInferior/PlateSprocket.STL" scale="0.004 0.004 0.004"/>
            </geometry>
        </visual> 
    </link>

    <link name="04_PlateSprocket">
        <visual>
            <origin xyz="0.55 -1.0 0.0" rpy="1.570795 0.0 0.0"/>
            <geometry>
                <mesh filename="package://ixnaminki_description/meshes/ASSY_TrenInferior/PlateSprocket.STL" scale="0.004 0.004 0.004"/>
            </geometry>
        </visual> 
    </link>

    <link name="01_Placa">
        <visual>
            <origin xyz="0.26 0.015 0.27" rpy="1.570795 ${PI} 0.0"/>
            <geometry>
                <mesh filename="package://ixnaminki_description/meshes/FLIPPER_ASSY/Placa.STL" scale="0.004 0.004 0.004"/>
            </geometry>
        </visual> 
    </link>

    <link name="02_Placa">
        <visual>
            <origin xyz="0.26 -0.015 0.27" rpy="1.570795 ${PI} 0.0"/>
            <geometry>
                <mesh filename="package://ixnaminki_description/meshes/FLIPPER_ASSY/Placa.STL" scale="0.004 0.004 0.004"/>
            </geometry>
        </visual> 
    </link>

    <link name="03_Placa">
        <visual>
            <origin xyz="-0.26 0.015 -0.27" rpy="1.570795 0.0 0.0"/>
            <geometry>
                <mesh filename="package://ixnaminki_description/meshes/FLIPPER_ASSY/Placa.STL" scale="0.004 0.004 0.004"/>
            </geometry>
        </visual> 
    </link>

    <link name="04_Placa">
        <visual>
            <origin xyz="-0.26 -0.015 -0.27" rpy="1.570795 0.0 0.0"/>
            <geometry>
                <mesh filename="package://ixnaminki_description/meshes/FLIPPER_ASSY/Placa.STL" scale="0.004 0.004 0.004"/>
            </geometry>
        </visual> 
    </link>

    <link name="01_FlatSprocket">
        <visual>
            <origin xyz="-0.55 0.0 -0.47" rpy="1.570795 0.0 0.0"/>
            <geometry>
                <mesh filename="package://ixnaminki_description/meshes/ASSY_TrenInferior/FlatSprocket.STL" scale="0.004 0.004 0.004"/>
            </geometry>
        </visual> 
    </link>


    <link name="02_FlatSprocket">
        <visual>
            <origin xyz="-0.55 0.0 -0.47" rpy="1.570795 0.0 0.0"/>
            <geometry>
                <mesh filename="package://ixnaminki_description/meshes/ASSY_TrenInferior/FlatSprocket.STL" scale="0.004 0.004 0.004"/>
            </geometry>
        </visual> 
    </link>

    <link name="03_FlatSprocket">
        <visual>
            <origin xyz="0.01 0.0 -0.492" rpy="1.570795 0.0 0.0"/>
            <geometry>
                <mesh filename="package://ixnaminki_description/meshes/ASSY_TrenInferior/FlatSprocket.STL" scale="0.004 0.004 0.004"/>
            </geometry>
        </visual> 
    </link>

    <link name="04_FlatSprocket">
        <visual>
            <origin xyz="0.01 0.0 -0.492" rpy="1.570795 0.0 0.0"/>
            <geometry>
                <mesh filename="package://ixnaminki_description/meshes/ASSY_TrenInferior/FlatSprocket.STL" scale="0.004 0.004 0.004"/>
            </geometry>
        </visual> 
    </link>




    <joint name="virtual_joint" type="fixed">
        <parent link="world"/>
        <child link="base_link"/>
        <origin xyz="0 0 0" rpy="0 0 0"/>
    </joint> 

    <joint name="joint_1" type="fixed">
        <origin xyz="0.0 0.0 0.0" rpy="0.0 0.0 0.0"/>
        <parent link="base_link"/>
        <child link="02_EjePrincipal"/>
    </joint>

    <joint name="joint_2" type="fixed">
        <origin xyz="0.0 0.0 0.0" rpy="0.0 0.0 0.0"/>
        <parent link="base_link"/>
        <child link="02_EjePrincipal2"/>
    </joint>

    <joint name="joint_3" type="fixed">
        <origin xyz="0.0 0.0 0.0" rpy="0.0 0.0 0.0"/>
        <parent link="02_EjePrincipal2"/>
        <child link="01_PlateSprocket"/>
    </joint>

    <joint name="joint_4" type="fixed">
        <origin xyz="0.0 0.0 0.0" rpy="0.0 0.0 0.0"/>
        <parent link="02_EjePrincipal2"/>
        <child link="02_PlateSprocket"/>
    </joint>

    <joint name="joint_5" type="fixed">
        <origin xyz="0.0 0.0 0.0" rpy="0.0 0.0 0.0"/>
        <parent link="02_EjePrincipal"/>
        <child link="03_PlateSprocket"/>
    </joint>

    <joint name="joint_6" type="fixed">
        <origin xyz="0.0 0.0 0.0" rpy="0.0 0.0 0.0"/>
        <parent link="02_EjePrincipal"/>
        <child link="04_PlateSprocket"/>
    </joint>


    <joint name ="joint_7" type="revolute">
        <parent link="02_EjePrincipal2"/>
        <child link = "01_Placa"/>
        <origin xyz="-0.69 1.0 0.28"/>
        <axis xyz="0 1 0"/>
        <limit lower="-1.570795" upper="1.570795" 
               effort="${effort}" velocity="${velocity}"/>
    </joint>

    <joint name ="joint_8" type="revolute">
        <parent link="02_EjePrincipal2"/>
        <child link = "02_Placa"/>
        <origin xyz="-0.69 -1.0 0.28"/>
        <axis xyz="0 1 0"/>
        <limit lower="-1.570795" upper="1.570795" 
               effort="${effort}" velocity="${velocity}"/>
    </joint>

    <joint name ="joint_9" type="revolute">
        <parent link="02_EjePrincipal"/>
        <child link = "03_Placa"/>
        <origin xyz="0.84 1.0 0.29"/>
        <axis xyz="0 1 0"/>
        <limit lower="-1.570795" upper="1.570795" 
               effort="${effort}" velocity="${velocity}"/>
    </joint>

    <joint name ="joint_10" type="revolute">
        <parent link="02_EjePrincipal"/>
        <child link = "04_Placa"/>
        <origin xyz="0.84 -1.0 0.29"/>
        <axis xyz="0 1 0"/>
        <limit lower="-1.570795" upper="1.570795" 
               effort="${effort}" velocity="${velocity}"/>
    </joint>


    <joint name="joint_11" type="fixed">
        <origin xyz="-0.69 -0.015 0.28" rpy="0.0 0.0 0.0"/>
        <parent link="01_Placa"/>
        <child link="01_FlatSprocket"/>
    </joint>

    <joint name="joint_12" type="fixed">
        <origin xyz="-0.69 0.015 0.28" rpy="0.0 0.0 0.0"/>
        <parent link="02_Placa"/>
        <child link="02_FlatSprocket"/>
    </joint>

    <joint name="joint_13" type="fixed">
        <origin xyz="0.84 -0.015 0.29" rpy="0.0 0.0 0.0"/>
        <parent link="03_Placa"/>
        <child link="03_FlatSprocket"/>
    </joint>

    <joint name="joint_14" type="fixed">
        <origin xyz="0.84 0.015 0.29" rpy="0.0 0.0 0.0"/>
        <parent link="04_Placa"/>
        <child link="04_FlatSprocket"/>
    </joint>
</robot>